<mujoco model="kxr_l2_humanoid">
  <compiler angle="degree" inertiafromgeom="true"/>
  <option integrator="RK4" timestep="0.002"/>
  <default>
    <joint armature="1" damping="1" limited="true"/>
    <geom conaffinity="0" condim="3" density="1000" friction="0.8 0.1 0.1" margin="0.001" rgba="0.8 0.6 0.4 1"/>
  </default>

  <worldbody>
    <light cutoff="100" diffuse="1 1 1" dir="-0 0 -1.3" directional="true" exponent="1" pos="0 0 1.3" specular=".1 .1 .1"/>
    <geom conaffinity="1" condim="3" name="floor" pos="0 0 0" rgba="0.8 0.9 0.8 1" size="40 40 40" type="plane"/>
    
    <body name="torso" pos="0 0 0.2955">
      <joint armature="0" damping="0" limited="false" name="root" pos="0 0 0" type="free"/>
      <geom name="torso1" pos="0 0 0" size="0.0765 0.05 0.0988" type="box"/>
      
      <body name="head" pos="0 0 0.1585">
        <joint name="head_pan" axis="0 0 1" range="-90 90" type="hinge"/>
        <joint name="head_tilt" axis="0 1 0" range="-45 45" type="hinge"/>
        <geom name="head" pos="0 0 0.05375" size="0.05375 0.05375 0.05375" type="box"/>
      </body>
      
      <body name="right_shoulder" pos="0 -0.0765 0.0988">
        <joint name="right_shoulder_pitch" axis="0 1 0" range="-180 180" type="hinge"/>
        <geom name="right_shoulder" size="0.0235 0.0235 0.0235" type="box"/>
        <body name="right_upper_arm" pos="0 -0.0235 0">
          <joint name="right_shoulder_roll" axis="1 0 0" range="-90 90" type="hinge"/>
          <geom name="right_upper_arm" pos="0 0 -0.0735" size="0.0235 0.0235 0.0735" type="box"/>
          <body name="right_lower_arm" pos="0 0 -0.147">
            <joint name="right_elbow" axis="0 1 0" range="-130 10" type="hinge"/>
            <geom name="right_lower_arm" pos="0 0 -0.0793" size="0.0235 0.0235 0.0793" type="box"/>
          </body>
        </body>
      </body>
      
      <body name="left_shoulder" pos="0 0.0765 0.0988">
        <joint name="left_shoulder_pitch" axis="0 1 0" range="-180 180" type="hinge"/>
        <geom name="left_shoulder" size="0.0235 0.0235 0.0235" type="box"/>
        <body name="left_upper_arm" pos="0 0.0235 0">
          <joint name="left_shoulder_roll" axis="1 0 0" range="-90 90" type="hinge"/>
          <geom name="left_upper_arm" pos="0 0 -0.0735" size="0.0235 0.0235 0.0735" type="box"/>
          <body name="left_lower_arm" pos="0 0 -0.147">
            <joint name="left_elbow" axis="0 1 0" range="-130 10" type="hinge"/>
            <geom name="left_lower_arm" pos="0 0 -0.0793" size="0.0235 0.0235 0.0793" type="box"/>
          </body>
        </body>
      </body>
      
      <body name="right_hip" pos="0 -0.038 -0.0988">
        <joint name="right_hip_yaw" axis="0 0 1" range="-90 90" type="hinge"/>
        <geom name="right_hip" size="0.029 0.029 0.029" type="box"/>
        <body name="right_upper_leg" pos="0 0 -0.029">
          <joint name="right_hip_roll" axis="1 0 0" range="-90 90" type="hinge"/>
          <joint name="right_hip_pitch" axis="0 1 0" range="-180 180" type="hinge"/>
          <geom name="right_upper_leg" pos="0 0 -0.0735" size="0.029 0.029 0.0735" type="box"/>
          <body name="right_lower_leg" pos="0 0 -0.147">
            <joint name="right_knee" axis="0 1 0" range="-130 10" type="hinge"/>
            <geom name="right_lower_leg" pos="0 0 -0.1213" size="0.029 0.029 0.1213" type="box"/>
            <body name="right_foot" pos="0 0 -0.2425">
              <joint name="right_ankle" axis="0 1 0" range="-45 45" type="hinge"/>
              <geom name="right_foot" pos="0.05 0 -0.0235" size="0.05 0.029 0.0235" type="box"/>
            </body>
          </body>
        </body>
      </body>
      
      <body name="left_hip" pos="0 0.038 -0.0988">
        <joint name="left_hip_yaw" axis="0 0 1" range="-90 90" type="hinge"/>
        <geom name="left_hip" size="0.029 0.029 0.029" type="box"/>
        <body name="left_upper_leg" pos="0 0 -0.029">
          <joint name="left_hip_roll" axis="1 0 0" range="-90 90" type="hinge"/>
          <joint name="left_hip_pitch" axis="0 1 0" range="-180 180" type="hinge"/>
          <geom name="left_upper_leg" pos="0 0 -0.0735" size="0.029 0.029 0.0735" type="box"/>
          <body name="left_lower_leg" pos="0 0 -0.147">
            <joint name="left_knee" axis="0 1 0" range="-130 10" type="hinge"/>
            <geom name="left_lower_leg" pos="0 0 -0.1213" size="0.029 0.029 0.1213" type="box"/>
            <body name="left_foot" pos="0 0 -0.2425">
              <joint name="left_ankle" axis="0 1 0" range="-45 45" type="hinge"/>
              <geom name="left_foot" pos="0.05 0 -0.0235" size="0.05 0.029 0.0235" type="box"/>
            </body>
          </body>
        </body>
      </body>
    </body>
  </worldbody>

  <actuator>
    <motor joint="head_pan" ctrlrange="-1 1" ctrllimited="true"/>
    <motor joint="head_tilt" ctrlrange="-1 1" ctrllimited="true"/>
    <motor joint="right_shoulder_pitch" ctrlrange="-1 1" ctrllimited="true"/>
    <motor joint="right_shoulder_roll" ctrlrange="-1 1" ctrllimited="true"/>
    <motor joint="right_elbow" ctrlrange="-1 1" ctrllimited="true"/>
    <motor joint="left_shoulder_pitch" ctrlrange="-1 1" ctrllimited="true"/>
    <motor joint="left_shoulder_roll" ctrlrange="-1 1" ctrllimited="true"/>
    <motor joint="left_elbow" ctrlrange="-1 1" ctrllimited="true"/>
    <motor joint="right_hip_yaw" ctrlrange="-1 1" ctrllimited="true"/>
    <motor joint="right_hip_roll" ctrlrange="-1 1" ctrllimited="true"/>
    <motor joint="right_hip_pitch" ctrlrange="-1 1" ctrllimited="true"/>
    <motor joint="right_knee" ctrlrange="-1 1" ctrllimited="true"/>
    <motor joint="right_ankle" ctrlrange="-1 1" ctrllimited="true"/>
    <motor joint="left_hip_yaw" ctrlrange="-1 1" ctrllimited="true"/>
    <motor joint="left_hip_roll" ctrlrange="-1 1" ctrllimited="true"/>
    <motor joint="left_hip_pitch" ctrlrange="-1 1" ctrllimited="true"/>
    <motor joint="left_knee" ctrlrange="-1 1" ctrllimited="true"/>
    <motor joint="left_ankle" ctrlrange="-1 1" ctrllimited="true"/>
  </actuator>
</mujoco>